[2024-04-16T13:12:36.519+0000] {taskinstance.py:1979} INFO - Dependencies all met for dep_context=non-requeueable deps ti=<TaskInstance: Units_statistics_DAG.split_data_into_chunks manual__2024-04-16T13:12:25.107688+00:00 [queued]>
[2024-04-16T13:12:36.531+0000] {taskinstance.py:1979} INFO - Dependencies all met for dep_context=requeueable deps ti=<TaskInstance: Units_statistics_DAG.split_data_into_chunks manual__2024-04-16T13:12:25.107688+00:00 [queued]>
[2024-04-16T13:12:36.531+0000] {taskinstance.py:2193} INFO - Starting attempt 1 of 4
[2024-04-16T13:12:36.552+0000] {taskinstance.py:2217} INFO - Executing <Task(_PythonDecoratedOperator): split_data_into_chunks> on 2024-04-16 13:12:25.107688+00:00
[2024-04-16T13:12:36.560+0000] {standard_task_runner.py:60} INFO - Started process 332595 to run task
[2024-04-16T13:12:36.566+0000] {standard_task_runner.py:87} INFO - Running: ['***', 'tasks', 'run', 'Units_statistics_DAG', 'split_data_into_chunks', 'manual__2024-04-16T13:12:25.107688+00:00', '--job-id', '4094', '--raw', '--subdir', 'DAGS_FOLDER/Units_dag.py', '--cfg-path', '/tmp/tmpee21ck8q']
[2024-04-16T13:12:36.568+0000] {standard_task_runner.py:88} INFO - Job 4094: Subtask split_data_into_chunks
[2024-04-16T13:12:36.640+0000] {task_command.py:423} INFO - Running <TaskInstance: Units_statistics_DAG.split_data_into_chunks manual__2024-04-16T13:12:25.107688+00:00 [running]> on host a09da322e808
[2024-04-16T13:12:36.760+0000] {taskinstance.py:2513} INFO - Exporting env vars: AIRFLOW_CTX_DAG_OWNER='abeer-araby' AIRFLOW_CTX_DAG_ID='Units_statistics_DAG' AIRFLOW_CTX_TASK_ID='split_data_into_chunks' AIRFLOW_CTX_EXECUTION_DATE='2024-04-16T13:12:25.107688+00:00' AIRFLOW_CTX_TRY_NUMBER='1' AIRFLOW_CTX_DAG_RUN_ID='manual__2024-04-16T13:12:25.107688+00:00'
[2024-04-16T13:12:36.780+0000] {Units_dag.py:69} INFO - type of length is :<class 'int'>
[2024-04-16T13:12:37.264+0000] {warnings.py:109} WARNING - /home/***/.local/lib/python3.8/site-packages/elasticsearch/_sync/client/__init__.py:399: SecurityWarning: Connecting to 'https://dbelk1.afaqy.local:9200' using TLS with verify_certs=False is insecure
  _transport = transport_class(

[2024-04-16T13:12:37.311+0000] {warnings.py:109} WARNING - /home/***/.local/lib/python3.8/site-packages/elasticsearch/_sync/client/__init__.py:399: SecurityWarning: Connecting to 'https://dbelk3.afaqy.local:9200' using TLS with verify_certs=False is insecure
  _transport = transport_class(

[2024-04-16T13:12:37.354+0000] {warnings.py:109} WARNING - /home/***/.local/lib/python3.8/site-packages/elasticsearch/_sync/client/__init__.py:399: SecurityWarning: Connecting to 'https://dbelk2.afaqy.local:9200' using TLS with verify_certs=False is insecure
  _transport = transport_class(

[2024-04-16T13:12:37.490+0000] {warnings.py:109} WARNING - /home/***/.local/lib/python3.8/site-packages/urllib3/connectionpool.py:1061: InsecureRequestWarning: Unverified HTTPS request is being made to host 'dbelk1.afaqy.local'. Adding certificate verification is strongly advised. See: https://urllib3.readthedocs.io/en/1.26.x/advanced-usage.html#ssl-warnings
  warnings.warn(

[2024-04-16T13:12:37.587+0000] {_transport.py:335} INFO - GET https://dbelk1.afaqy.local:9200/_cluster/health [status:200 duration:0.230s]
[2024-04-16T13:12:37.612+0000] {warnings.py:109} WARNING - /home/***/.local/lib/python3.8/site-packages/urllib3/connectionpool.py:1061: InsecureRequestWarning: Unverified HTTPS request is being made to host 'dbelk3.afaqy.local'. Adding certificate verification is strongly advised. See: https://urllib3.readthedocs.io/en/1.26.x/advanced-usage.html#ssl-warnings
  warnings.warn(

[2024-04-16T13:12:37.625+0000] {_transport.py:335} INFO - HEAD https://dbelk3.afaqy.local:9200/units_statistics_*** [status:200 duration:0.036s]
[2024-04-16T13:12:37.709+0000] {warnings.py:109} WARNING - /home/***/.local/lib/python3.8/site-packages/urllib3/connectionpool.py:1061: InsecureRequestWarning: Unverified HTTPS request is being made to host 'dbelk2.afaqy.local'. Adding certificate verification is strongly advised. See: https://urllib3.readthedocs.io/en/1.26.x/advanced-usage.html#ssl-warnings
  warnings.warn(

[2024-04-16T13:12:38.582+0000] {_transport.py:335} INFO - DELETE https://dbelk2.afaqy.local:9200/units_statistics_*** [status:404 duration:0.956s]
[2024-04-16T13:12:38.583+0000] {taskinstance.py:2731} ERROR - Task failed with exception
Traceback (most recent call last):
  File "/home/airflow/.local/lib/python3.8/site-packages/airflow/models/taskinstance.py", line 444, in _execute_task
    result = _execute_callable(context=context, **execute_callable_kwargs)
  File "/home/airflow/.local/lib/python3.8/site-packages/airflow/models/taskinstance.py", line 414, in _execute_callable
    return execute_callable(context=context, **execute_callable_kwargs)
  File "/home/airflow/.local/lib/python3.8/site-packages/airflow/decorators/base.py", line 241, in execute
    return_value = super().execute(context)
  File "/home/airflow/.local/lib/python3.8/site-packages/airflow/operators/python.py", line 200, in execute
    return_value = self.execute_callable()
  File "/home/airflow/.local/lib/python3.8/site-packages/airflow/operators/python.py", line 217, in execute_callable
    return self.python_callable(*self.op_args, **self.op_kwargs)
  File "/opt/airflow/dags/Units_dag.py", line 77, in split_data_into_chunks
    Elk_client.delete_index(Globals.index_name)
  File "/opt/airflow/dags/elk_manager.py", line 74, in delete_index
    result = self.elk_client.indices.delete(index=index_name)
  File "/home/airflow/.local/lib/python3.8/site-packages/elasticsearch/_sync/client/utils.py", line 446, in wrapped
    return api(*args, **kwargs)
  File "/home/airflow/.local/lib/python3.8/site-packages/elasticsearch/_sync/client/indices.py", line 671, in delete
    return self.perform_request(  # type: ignore[return-value]
  File "/home/airflow/.local/lib/python3.8/site-packages/elasticsearch/_sync/client/_base.py", line 389, in perform_request
    return self._client.perform_request(
  File "/home/airflow/.local/lib/python3.8/site-packages/elasticsearch/_sync/client/_base.py", line 320, in perform_request
    raise HTTP_EXCEPTIONS.get(meta.status, ApiError)(
elasticsearch.NotFoundError: NotFoundError(404, 'index_not_found_exception', 'no such index [units_statistics_airflow]')
[2024-04-16T13:12:38.600+0000] {taskinstance.py:1149} INFO - Marking task as UP_FOR_RETRY. dag_id=Units_statistics_DAG, task_id=split_data_into_chunks, execution_date=20240416T131225, start_date=20240416T131236, end_date=20240416T131238
[2024-04-16T13:12:38.616+0000] {standard_task_runner.py:107} ERROR - Failed to execute job 4094 for task split_data_into_chunks (NotFoundError(404, 'index_not_found_exception', 'no such index [units_statistics_airflow]'); 332595)
[2024-04-16T13:12:38.667+0000] {local_task_job_runner.py:234} INFO - Task exited with return code 1
[2024-04-16T13:12:38.712+0000] {taskinstance.py:3312} INFO - 0 downstream tasks scheduled from follow-on schedule check
