[2024-05-07T10:00:15.908+0000] {taskinstance.py:1979} INFO - Dependencies all met for dep_context=non-requeueable deps ti=<TaskInstance: Units_statistics_DAG.ETL_job scheduled__2024-05-07T09:40:00+00:00 map_index=13 [queued]>
[2024-05-07T10:00:16.006+0000] {taskinstance.py:1979} INFO - Dependencies all met for dep_context=requeueable deps ti=<TaskInstance: Units_statistics_DAG.ETL_job scheduled__2024-05-07T09:40:00+00:00 map_index=13 [queued]>
[2024-05-07T10:00:16.006+0000] {taskinstance.py:2193} INFO - Starting attempt 1 of 4
[2024-05-07T10:00:16.127+0000] {taskinstance.py:2217} INFO - Executing <Mapped(_PythonDecoratedOperator): ETL_job> on 2024-05-07 09:40:00+00:00
[2024-05-07T10:00:16.139+0000] {standard_task_runner.py:60} INFO - Started process 831008 to run task
[2024-05-07T10:00:16.187+0000] {standard_task_runner.py:87} INFO - Running: ['***', 'tasks', 'run', 'Units_statistics_DAG', 'ETL_job', 'scheduled__2024-05-07T09:40:00+00:00', '--job-id', '38022', '--raw', '--subdir', 'DAGS_FOLDER/Units_dag.py', '--cfg-path', '/tmp/tmplmban44s', '--map-index', '13']
[2024-05-07T10:00:16.189+0000] {standard_task_runner.py:88} INFO - Job 38022: Subtask ETL_job
[2024-05-07T10:00:16.431+0000] {task_command.py:423} INFO - Running <TaskInstance: Units_statistics_DAG.ETL_job scheduled__2024-05-07T09:40:00+00:00 map_index=13 [running]> on host a09da322e808
[2024-05-07T10:00:16.828+0000] {taskinstance.py:2513} INFO - Exporting env vars: AIRFLOW_CTX_DAG_OWNER='abeer-araby' AIRFLOW_CTX_DAG_ID='Units_statistics_DAG' AIRFLOW_CTX_TASK_ID='ETL_job' AIRFLOW_CTX_EXECUTION_DATE='2024-05-07T09:40:00+00:00' AIRFLOW_CTX_TRY_NUMBER='1' AIRFLOW_CTX_DAG_RUN_ID='scheduled__2024-05-07T09:40:00+00:00'
[2024-05-07T10:00:16.829+0000] {Units_dag.py:98} INFO - i: 130000, chunk: 10000
[2024-05-07T10:00:16.829+0000] {Units_dag.py:99} INFO - child token is::: eyJ0eXAiOiJKV1QiLCJhbGciOiJIUzI1NiJ9.eyJpc3MiOiJodHRwczovL2FwaS5hZmFxeS5zYS9hdXRoL2xvZ2luX2FzIiwiaWF0IjoxNzE1MDc2MDA0LCJleHAiOjE3MTc2NjgwMDQsIm5iZiI6MTcxNTA3NjAwNCwianRpIjoiOTBYb081V3hRQjU5b29FcyIsInN1YiI6IjVkNjNlNTFlMDNlZDUyOTJhNDJjMjRlNiIsInBydiI6IjI3MGVjZmM3ZWEzZWQ5MzdlYTg0OTM2MmEzYTUwOTEwYzZkOGNlNGYiLCJsb2dpbl9hc19pZCI6IjY1N2YwYWQ3M2Y5NzcyOTVjZjA1NTc2YSJ9.MBS7WGCDTYC8iW5ibR9WoQLxUD5oQuHO8ynm4vO0kak
[2024-05-07T10:00:50.002+0000] {Units_dag.py:103} INFO - {'_id': '650eeaed1506573b903bb9ca', 'icon': 'icons/icon.png', 'driver_id': '', 'tailer_id': '', 'profile': {'vehicle_type': '', 'measurement_type': 'count', 'max_capacity': 0, 'vin': '', 'plate_number': '', 'start_operation': '', 'contract_milage': '', 'opening_milage': '', 'model': '', 'fuel_type': '91', 'year': 0, 'seats': 2}, 'shipment_info': {'product_category': None, 'truck_type': None, 'shipment_type': None, 'shipment_payment_type': None, 'transporter_type': None, 'operating_area': None, 'weight_kilograms_per_day': None, 'kms_per_day': None, 'shipment_trip_drive_hrs_day': None, 'allowable_delay_drive_hrs_day': None, 'expected_shipment_trip_day': None, 'car_pay_per_day': None, 'exceeding_temperature_limit_per_day': None, 'temperature_upper_limit': None, 'exceeding_humidity_limit_per_day': None, 'humidity_upper_limit': None}, 'device_password': '***', 'device_type': 'gps', 'gateway': False, 'business_types': {'waste': False, 'transportation': True, 'water': False}, 'name': '76/5', 'operation_code': 'ا ب ن 3551', 'device_gateway': '', 'skip_sim_information': False, 'imei': '867994060796451', 'sim_number': '+966830031855879', 'sim_serial': '421296750917', 'device_serial': '867994060796451', 'device': 'bce', 'user_id': '64f73773e778317e9c5e3b5a', 'created_by': '5e6655bf03ed52e1ab79d301', 'updated_at': '2024-05-01 08:47:39', 'created_at': '2023-09-23 16:41:01', 'custom_fields': [], 'creator': 'amr.ahmed', 'company': '', 'owner': 'elaf-aseer-admin', 'last_update': {'dtt': 1715075452000, 'dts': 1715075627684, 'spd': 0, 'ang': 258, 'alt': 1999, 'chPrams': {'ePwrV': {'v': 24.789, 'cdt': 1715075452000}, 'di16': {'v': 1, 'cdt': 1713121564000}, 'rssi1': {'v': 63, 'cdt': 1715075452000}, 'di15': {'v': 0, 'cdt': 1713121564000}, 'di14': {'v': 0, 'cdt': 1714581428000}, 'di13': {'v': 0, 'cdt': 1713121564000}, 'di12': {'v': 0, 'cdt': 1713121564000}, 'di11': {'v': 0, 'cdt': 1713121564000}, 'di10': {'v': 0, 'cdt': 1713121564000}, 'di2': {'v': 1, 'cdt': 1713991776000}, 'ai4': {'v': 10988, 'cdt': 1715075452000}, 'di1': {'v': 0, 'cdt': 1714585256000}, 'di4': {'v': 0, 'cdt': 1713121564000}, 'di3': {'v': 0, 'cdt': 1713121564000}, 'di6': {'v': 0, 'cdt': 1713121564000}, 'di5': {'v': 0, 'cdt': 1714584326000}, 'lac1': {'v': 62012, 'cdt': 1712804150000}, 'protocol': {'v': 'bce', 'cdt': 1713121564000}, 'di8': {'v': 1, 'cdt': 1713991776000}, 'di7': {'v': 0, 'cdt': 1714584356000}, 'di9': {'v': 0, 'cdt': 1713121564000}, 'iPwrV': {'v': 0.014, 'cdt': 1715073652000}, 'cid1': {'v': 14683, 'cdt': 1714687556000}, 'odometer': {'v': 0, 'cdt': 1714219472000}, 'spd': {'v': 0, 'cdt': 1714584086000}, 'sat': {'v': 12, 'cdt': 1714944052000}, 'hdop': {'v': 1, 'cdt': 1714404370000}, 'ta': {'v': 0, 'cdt': 1713121564000}, 'mcc1': {'v': 420, 'cdt': 1713759892000}, 'mnc1': {'v': 4, 'cdt': 1713759892000}}, 'prms': {'protocol': 'bce', 'spd': 0, 'sat': 12, 'hdop': 1, 'odometer': 0, 'di16': 1, 'di15': 0, 'di14': 0, 'di13': 0, 'di12': 0, 'di11': 0, 'di10': 0, 'di9': 0, 'di8': 1, 'di7': 0, 'di6': 0, 'di5': 0, 'di4': 0, 'di3': 0, 'di2': 1, 'di1': 0, 'ePwrV': 24.789, 'ai4': 10988, 'iPwrV': 0.014, 'ta': 0, 'mcc1': 420, 'mnc1': 4, 'lac1': 62012, 'cid1': 14683, 'rssi1': 63}, 'devPrms': ['protocol', 'spd', 'sat', 'hdop', 'odometer', 'di16', 'di15', 'di14', 'di13', 'di12', 'di11', 'di10', 'di9', 'di8', 'di7', 'di6', 'di5', 'di4', 'di3', 'di2', 'di1', 'ePwrV', 'ai4', 'iPwrV', 'ta', 'mcc1', 'mnc1', 'lac1', 'cid1', 'rssi1'], 'old_params': {'protocol': 'bce', 'spd': 0, 'sat': 12, 'hdop': 1, 'odometer': 0, 'di16': 1, 'di15': 0, 'di14': 0, 'di13': 0, 'di12': 0, 'di11': 0, 'di10': 0, 'di9': 0, 'di8': 1, 'di7': 0, 'di6': 0, 'di5': 0, 'di4': 0, 'di3': 0, 'di2': 1, 'di1': 0, 'ePwrV': 24.824, 'ai4': 10957, 'iPwrV': 0.014, 'ta': 0, 'mcc1': 420, 'mnc1': 4, 'lac1': 62012, 'cid1': 14683, 'rssi1': 67}, 'vLoc': 1, 'vCon': 1, 'ip': '51.39.53.242', 'rl': 0, 'trl': 5184.5329, 'mdu': 0, 'tmdu': 574102, 'eidl': 0, 'teidl': 692686, 'fc': 0, 'tfc': 0.04836, 'acc': 0, 'accOn': 4297206, 'accOff': 16625782, 'sdu': 300, 'tsdu': 491126, 'lat': 18.31985092163086, 'lng': 42.70068359375}, 'counters': {'odometer_type': 'gps', 'odometer': 5184.313, 'engine_hours_type': 'acc', 'engine_hours': 4297206, 'last_acc': 0}, 'is_wasl_connected': 'Not Connected', 'iconUrl': 'https://api.afaqy.sa/images/units/icons/icon.png', 'hasCCTV': False}
[2024-05-07T10:00:51.957+0000] {warnings.py:109} WARNING - /home/***/.local/lib/python3.8/site-packages/elasticsearch/_sync/client/__init__.py:399: SecurityWarning: Connecting to 'https://dbelk3.afaqy.local:9200' using TLS with verify_certs=False is insecure
  _transport = transport_class(

[2024-05-07T10:01:03.810+0000] {job.py:213} ERROR - Job heartbeat got an exception
Traceback (most recent call last):
  File "/home/airflow/.local/lib/python3.8/site-packages/sqlalchemy/engine/base.py", line 3371, in _wrap_pool_connect
    return fn()
  File "/home/airflow/.local/lib/python3.8/site-packages/sqlalchemy/pool/base.py", line 327, in connect
    return _ConnectionFairy._checkout(self)
  File "/home/airflow/.local/lib/python3.8/site-packages/sqlalchemy/pool/base.py", line 894, in _checkout
    fairy = _ConnectionRecord.checkout(pool)
  File "/home/airflow/.local/lib/python3.8/site-packages/sqlalchemy/pool/base.py", line 493, in checkout
    rec = pool._do_get()
  File "/home/airflow/.local/lib/python3.8/site-packages/sqlalchemy/pool/impl.py", line 256, in _do_get
    return self._create_connection()
  File "/home/airflow/.local/lib/python3.8/site-packages/sqlalchemy/pool/base.py", line 273, in _create_connection
    return _ConnectionRecord(self)
  File "/home/airflow/.local/lib/python3.8/site-packages/sqlalchemy/pool/base.py", line 388, in __init__
    self.__connect()
  File "/home/airflow/.local/lib/python3.8/site-packages/sqlalchemy/pool/base.py", line 691, in __connect
    pool.logger.debug("Error on connect(): %s", e)
  File "/home/airflow/.local/lib/python3.8/site-packages/sqlalchemy/util/langhelpers.py", line 70, in __exit__
    compat.raise_(
  File "/home/airflow/.local/lib/python3.8/site-packages/sqlalchemy/util/compat.py", line 211, in raise_
    raise exception
  File "/home/airflow/.local/lib/python3.8/site-packages/sqlalchemy/pool/base.py", line 686, in __connect
    self.dbapi_connection = connection = pool._invoke_creator(self)
  File "/home/airflow/.local/lib/python3.8/site-packages/sqlalchemy/engine/create.py", line 574, in connect
    return dialect.connect(*cargs, **cparams)
  File "/home/airflow/.local/lib/python3.8/site-packages/sqlalchemy/engine/default.py", line 598, in connect
    return self.dbapi.connect(*cargs, **cparams)
  File "/home/airflow/.local/lib/python3.8/site-packages/psycopg2/__init__.py", line 122, in connect
    conn = _connect(dsn, connection_factory=connection_factory, **kwasync)
psycopg2.OperationalError: could not translate host name "postgres" to address: Temporary failure in name resolution


The above exception was the direct cause of the following exception:

Traceback (most recent call last):
  File "/home/airflow/.local/lib/python3.8/site-packages/airflow/jobs/job.py", line 187, in heartbeat
    self._merge_from(Job._fetch_from_db(self, session))
  File "/home/airflow/.local/lib/python3.8/site-packages/airflow/api_internal/internal_api_call.py", line 114, in wrapper
    return func(*args, **kwargs)
  File "/home/airflow/.local/lib/python3.8/site-packages/airflow/utils/session.py", line 76, in wrapper
    return func(*args, **kwargs)
  File "/home/airflow/.local/lib/python3.8/site-packages/airflow/jobs/job.py", line 308, in _fetch_from_db
    session.merge(job)
  File "/home/airflow/.local/lib/python3.8/site-packages/sqlalchemy/orm/session.py", line 3056, in merge
    return self._merge(
  File "/home/airflow/.local/lib/python3.8/site-packages/sqlalchemy/orm/session.py", line 3136, in _merge
    merged = self.get(
  File "/home/airflow/.local/lib/python3.8/site-packages/sqlalchemy/orm/session.py", line 2853, in get
    return self._get_impl(
  File "/home/airflow/.local/lib/python3.8/site-packages/sqlalchemy/orm/session.py", line 2975, in _get_impl
    return db_load_fn(
  File "/home/airflow/.local/lib/python3.8/site-packages/sqlalchemy/orm/loading.py", line 530, in load_on_pk_identity
    session.execute(
  File "/home/airflow/.local/lib/python3.8/site-packages/sqlalchemy/orm/session.py", line 1716, in execute
    conn = self._connection_for_bind(bind)
  File "/home/airflow/.local/lib/python3.8/site-packages/sqlalchemy/orm/session.py", line 1555, in _connection_for_bind
    return self._transaction._connection_for_bind(
  File "/home/airflow/.local/lib/python3.8/site-packages/sqlalchemy/orm/session.py", line 750, in _connection_for_bind
    conn = bind.connect()
  File "/home/airflow/.local/lib/python3.8/site-packages/sqlalchemy/future/engine.py", line 412, in connect
    return super(Engine, self).connect()
  File "/home/airflow/.local/lib/python3.8/site-packages/sqlalchemy/engine/base.py", line 3325, in connect
    return self._connection_cls(self, close_with_result=close_with_result)
  File "/home/airflow/.local/lib/python3.8/site-packages/sqlalchemy/engine/base.py", line 96, in __init__
    else engine.raw_connection()
  File "/home/airflow/.local/lib/python3.8/site-packages/sqlalchemy/engine/base.py", line 3404, in raw_connection
    return self._wrap_pool_connect(self.pool.connect, _connection)
  File "/home/airflow/.local/lib/python3.8/site-packages/sqlalchemy/engine/base.py", line 3374, in _wrap_pool_connect
    Connection._handle_dbapi_exception_noconnection(
  File "/home/airflow/.local/lib/python3.8/site-packages/sqlalchemy/engine/base.py", line 2208, in _handle_dbapi_exception_noconnection
    util.raise_(
  File "/home/airflow/.local/lib/python3.8/site-packages/sqlalchemy/util/compat.py", line 211, in raise_
    raise exception
  File "/home/airflow/.local/lib/python3.8/site-packages/sqlalchemy/engine/base.py", line 3371, in _wrap_pool_connect
    return fn()
  File "/home/airflow/.local/lib/python3.8/site-packages/sqlalchemy/pool/base.py", line 327, in connect
    return _ConnectionFairy._checkout(self)
  File "/home/airflow/.local/lib/python3.8/site-packages/sqlalchemy/pool/base.py", line 894, in _checkout
    fairy = _ConnectionRecord.checkout(pool)
  File "/home/airflow/.local/lib/python3.8/site-packages/sqlalchemy/pool/base.py", line 493, in checkout
    rec = pool._do_get()
  File "/home/airflow/.local/lib/python3.8/site-packages/sqlalchemy/pool/impl.py", line 256, in _do_get
    return self._create_connection()
  File "/home/airflow/.local/lib/python3.8/site-packages/sqlalchemy/pool/base.py", line 273, in _create_connection
    return _ConnectionRecord(self)
  File "/home/airflow/.local/lib/python3.8/site-packages/sqlalchemy/pool/base.py", line 388, in __init__
    self.__connect()
  File "/home/airflow/.local/lib/python3.8/site-packages/sqlalchemy/pool/base.py", line 691, in __connect
    pool.logger.debug("Error on connect(): %s", e)
  File "/home/airflow/.local/lib/python3.8/site-packages/sqlalchemy/util/langhelpers.py", line 70, in __exit__
    compat.raise_(
  File "/home/airflow/.local/lib/python3.8/site-packages/sqlalchemy/util/compat.py", line 211, in raise_
    raise exception
  File "/home/airflow/.local/lib/python3.8/site-packages/sqlalchemy/pool/base.py", line 686, in __connect
    self.dbapi_connection = connection = pool._invoke_creator(self)
  File "/home/airflow/.local/lib/python3.8/site-packages/sqlalchemy/engine/create.py", line 574, in connect
    return dialect.connect(*cargs, **cparams)
  File "/home/airflow/.local/lib/python3.8/site-packages/sqlalchemy/engine/default.py", line 598, in connect
    return self.dbapi.connect(*cargs, **cparams)
  File "/home/airflow/.local/lib/python3.8/site-packages/psycopg2/__init__.py", line 122, in connect
    conn = _connect(dsn, connection_factory=connection_factory, **kwasync)
sqlalchemy.exc.OperationalError: (psycopg2.OperationalError) could not translate host name "postgres" to address: Temporary failure in name resolution

(Background on this error at: https://sqlalche.me/e/14/e3q8)
[2024-05-07T10:01:03.940+0000] {job.py:221} ERROR - Job heartbeat failed with error. Scheduler is in unhealthy state
[2024-05-07T10:01:04.290+0000] {warnings.py:109} WARNING - /home/***/.local/lib/python3.8/site-packages/elasticsearch/_sync/client/__init__.py:399: SecurityWarning: Connecting to 'https://dbelk2.afaqy.local:9200' using TLS with verify_certs=False is insecure
  _transport = transport_class(

[2024-05-07T10:01:04.659+0000] {warnings.py:109} WARNING - /home/***/.local/lib/python3.8/site-packages/elasticsearch/_sync/client/__init__.py:399: SecurityWarning: Connecting to 'https://dbelk1.afaqy.local:9200' using TLS with verify_certs=False is insecure
  _transport = transport_class(

[2024-05-07T10:01:04.687+0000] {warnings.py:109} WARNING - /home/***/.local/lib/python3.8/site-packages/urllib3/connectionpool.py:1061: InsecureRequestWarning: Unverified HTTPS request is being made to host 'dbelk3.afaqy.local'. Adding certificate verification is strongly advised. See: https://urllib3.readthedocs.io/en/1.26.x/advanced-usage.html#ssl-warnings
  warnings.warn(

[2024-05-07T10:01:04.765+0000] {_transport.py:335} INFO - GET https://dbelk3.afaqy.local:9200/_cluster/health [status:200 duration:0.102s]
[2024-05-07T10:01:25.749+0000] {job.py:221} ERROR - Job heartbeat failed with error. Scheduler is in unhealthy state
[2024-05-07T10:01:25.832+0000] {warnings.py:109} WARNING - /home/***/.local/lib/python3.8/site-packages/urllib3/connectionpool.py:1061: InsecureRequestWarning: Unverified HTTPS request is being made to host 'dbelk2.afaqy.local'. Adding certificate verification is strongly advised. See: https://urllib3.readthedocs.io/en/1.26.x/advanced-usage.html#ssl-warnings
  warnings.warn(

[2024-05-07T10:01:25.924+0000] {_transport.py:358} INFO - PUT https://dbelk2.afaqy.local:9200/units_statistics_***/_bulk [status:N/A duration:20.062s]
[2024-05-07T10:01:25.927+0000] {_node_pool.py:249} WARNING - Node <Urllib3HttpNode(https://dbelk2.afaqy.local:9200)> has failed for 1 times in a row, putting on 1 second timeout
[2024-05-07T10:01:25.934+0000] {_transport.py:395} WARNING - Retrying request after failure (attempt 0 of 3)
Traceback (most recent call last):
  File "/home/airflow/.local/lib/python3.8/site-packages/elastic_transport/_transport.py", line 328, in perform_request
    meta, raw_data = node.perform_request(
  File "/home/airflow/.local/lib/python3.8/site-packages/elastic_transport/_node/_http_urllib3.py", line 202, in perform_request
    raise err from None
elastic_transport.ConnectionError: Connection error caused by: ProtocolError(('Connection aborted.', RemoteDisconnected('Remote end closed connection without response')))
[2024-05-07T10:01:26.034+0000] {warnings.py:109} WARNING - /home/***/.local/lib/python3.8/site-packages/urllib3/connectionpool.py:1061: InsecureRequestWarning: Unverified HTTPS request is being made to host 'dbelk3.afaqy.local'. Adding certificate verification is strongly advised. See: https://urllib3.readthedocs.io/en/1.26.x/advanced-usage.html#ssl-warnings
  warnings.warn(

[2024-05-07T10:01:26.259+0000] {_transport.py:335} INFO - PUT https://dbelk3.afaqy.local:9200/units_statistics_***/_bulk [status:429 duration:0.225s]
[2024-05-07T10:01:26.260+0000] {_node_pool.py:249} WARNING - Node <Urllib3HttpNode(https://dbelk3.afaqy.local:9200)> has failed for 1 times in a row, putting on 1 second timeout
[2024-05-07T10:01:26.260+0000] {_transport.py:427} WARNING - Retrying request after non-successful status 429 (attempt 1 of 3)
[2024-05-07T10:01:26.292+0000] {warnings.py:109} WARNING - /home/***/.local/lib/python3.8/site-packages/urllib3/connectionpool.py:1061: InsecureRequestWarning: Unverified HTTPS request is being made to host 'dbelk1.afaqy.local'. Adding certificate verification is strongly advised. See: https://urllib3.readthedocs.io/en/1.26.x/advanced-usage.html#ssl-warnings
  warnings.warn(

[2024-05-07T10:01:28.382+0000] {_transport.py:335} INFO - PUT https://dbelk1.afaqy.local:9200/units_statistics_***/_bulk [status:200 duration:2.122s]
[2024-05-07T10:01:28.608+0000] {python.py:202} INFO - Done. Returned value was: None
[2024-05-07T10:01:28.623+0000] {taskinstance.py:1149} INFO - Marking task as SUCCESS. dag_id=Units_statistics_DAG, task_id=ETL_job, map_index=13, execution_date=20240507T094000, start_date=20240507T100015, end_date=20240507T100128
[2024-05-07T10:01:28.688+0000] {local_task_job_runner.py:234} INFO - Task exited with return code 0
[2024-05-07T10:01:28.712+0000] {taskinstance.py:3312} INFO - 0 downstream tasks scheduled from follow-on schedule check
