[2024-04-16T06:11:11.470+0000] {taskinstance.py:1979} INFO - Dependencies all met for dep_context=non-requeueable deps ti=<TaskInstance: Units_statistics_DAG.ETL_job scheduled__2024-04-16T05:00:00+00:00 map_index=15 [queued]>
[2024-04-16T06:11:11.485+0000] {taskinstance.py:1979} INFO - Dependencies all met for dep_context=requeueable deps ti=<TaskInstance: Units_statistics_DAG.ETL_job scheduled__2024-04-16T05:00:00+00:00 map_index=15 [queued]>
[2024-04-16T06:11:11.486+0000] {taskinstance.py:2193} INFO - Starting attempt 3 of 4
[2024-04-16T06:11:11.505+0000] {taskinstance.py:2217} INFO - Executing <Mapped(_PythonDecoratedOperator): ETL_job> on 2024-04-16 05:00:00+00:00
[2024-04-16T06:11:11.511+0000] {standard_task_runner.py:60} INFO - Started process 325827 to run task
[2024-04-16T06:11:11.523+0000] {standard_task_runner.py:87} INFO - Running: ['***', 'tasks', 'run', 'Units_statistics_DAG', 'ETL_job', 'scheduled__2024-04-16T05:00:00+00:00', '--job-id', '3753', '--raw', '--subdir', 'DAGS_FOLDER/Units_dag.py', '--cfg-path', '/tmp/tmp5v2u0dmt', '--map-index', '15']
[2024-04-16T06:11:11.525+0000] {standard_task_runner.py:88} INFO - Job 3753: Subtask ETL_job
[2024-04-16T06:11:11.614+0000] {task_command.py:423} INFO - Running <TaskInstance: Units_statistics_DAG.ETL_job scheduled__2024-04-16T05:00:00+00:00 map_index=15 [running]> on host a09da322e808
[2024-04-16T06:11:11.776+0000] {taskinstance.py:2513} INFO - Exporting env vars: AIRFLOW_CTX_DAG_OWNER='abeer-araby' AIRFLOW_CTX_DAG_ID='Units_statistics_DAG' AIRFLOW_CTX_TASK_ID='ETL_job' AIRFLOW_CTX_EXECUTION_DATE='2024-04-16T05:00:00+00:00' AIRFLOW_CTX_TRY_NUMBER='3' AIRFLOW_CTX_DAG_RUN_ID='scheduled__2024-04-16T05:00:00+00:00'
[2024-04-16T06:11:11.777+0000] {Units_dag.py:90} INFO - i: 150000, chunk: 10000
[2024-04-16T06:11:11.777+0000] {Units_dag.py:91} INFO - child token is::: eyJ0eXAiOiJKV1QiLCJhbGciOiJIUzI1NiJ9.eyJpc3MiOiJodHRwczovL2FwaS5hZmFxeS5zYS9hdXRoL2xvZ2luX2FzIiwiaWF0IjoxNzEzMjQ3MjAzLCJleHAiOjE3MTU4MzkyMDMsIm5iZiI6MTcxMzI0NzIwMywianRpIjoiNTZnRE9CazJDbUxkeEI4QSIsInN1YiI6IjVkNjNlNTFlMDNlZDUyOTJhNDJjMjRlNiIsInBydiI6IjI3MGVjZmM3ZWEzZWQ5MzdlYTg0OTM2MmEzYTUwOTEwYzZkOGNlNGYiLCJsb2dpbl9hc19pZCI6IjY1N2YwYWQ3M2Y5NzcyOTVjZjA1NTc2YSJ9.BF8kX6oXeAry1pLVV40NWpIUTlTjKw-wzdZ4yxV71cM
[2024-04-16T06:11:32.623+0000] {Units_dag.py:95} INFO - {'_id': '658fe6dcb76b4dd95c0b32dd', 'icon': 'icons/icon.png', 'driver_id': '', 'tailer_id': '', 'profile': {'vehicle_type': '', 'measurement_type': 'count', 'max_capacity': 0, 'vin': '', 'plate_number': '2961 Z S A', 'start_operation': '', 'contract_milage': '', 'opening_milage': '', 'model': '', 'fuel_type': '91', 'year': 0, 'seats': 2}, 'shipment_info': {'product_category': None, 'truck_type': None, 'shipment_type': None, 'shipment_payment_type': None, 'transporter_type': None, 'operating_area': None, 'weight_kilograms_per_day': None, 'kms_per_day': None, 'shipment_trip_drive_hrs_day': None, 'allowable_delay_drive_hrs_day': None, 'expected_shipment_trip_day': None, 'car_pay_per_day': None, 'exceeding_temperature_limit_per_day': None, 'temperature_upper_limit': None, 'exceeding_humidity_limit_per_day': None, 'humidity_upper_limit': None}, 'device_password': '***', 'device_type': 'gps', 'gateway': False, 'business_types': {'waste': False, 'transportation': False, 'water': False}, 'name': '2961 Z S A', 'operation_code': '', 'device_gateway': '', 'skip_sim_information': '', 'imei': '867994060710791', 'sim_number': '+966830032499609', 'sim_serial': '8996609821111921445', 'device_serial': '867994060710791', 'device': 'bce', 'user_id': '637213dea4156a5c0106f36d', 'created_by': '6356629e8c90de353b0fb6b9', 'updated_at': '2024-02-11 06:10:34', 'created_at': '2023-12-30 12:46:04', 'creator': 'm.hisham', 'company': '', 'owner': 'tashilat-alturuq-admin', 'last_update': {'dtt': 1713247824000, 'dts': 1713247857861, 'spd': 7, 'ang': 306, 'alt': 2073, 'chPrams': {'ePwrV': {'v': 29.025, 'cdt': 1713247824000}, 'di16': {'v': 1, 'cdt': 1712735722000}, 'rssi1': {'v': 96, 'cdt': 1713247824000}, 'di15': {'v': 0, 'cdt': 1707550782000}, 'di14': {'v': 0, 'cdt': 1713211246000}, 'di13': {'v': 0, 'cdt': 1712735722000}, 'di12': {'v': 0, 'cdt': 1712735722000}, 'di11': {'v': 0, 'cdt': 1712735722000}, 'di10': {'v': 0, 'cdt': 1712735722000}, 'di2': {'v': 0, 'cdt': 1713199070000}, 'ai4': {'v': 1445, 'cdt': 1713247824000}, 'di1': {'v': 1, 'cdt': 1713247794000}, 'di4': {'v': 0, 'cdt': 1712735722000}, 'di3': {'v': 0, 'cdt': 1712735722000}, 'di6': {'v': 0, 'cdt': 1712735722000}, 'di5': {'v': 1, 'cdt': 1713246926000}, 'lac1': {'v': 7771, 'cdt': 1713247286000}, 'protocol': {'v': 'bce', 'cdt': 1712735722000}, 'di8': {'v': 1, 'cdt': 1712855098000}, 'di7': {'v': 1, 'cdt': 1713246956000}, 'di9': {'v': 0, 'cdt': 1712735722000}, 'iPwrV': {'v': 4.054, 'cdt': 1713243370000}, 'cid1': {'v': 49143, 'cdt': 1713247286000}, 'odometer': {'v': 0, 'cdt': 1713211304000}, 'spd': {'v': 7, 'cdt': 1713247824000}, 'sat': {'v': 12, 'cdt': 1713208804000}, 'hdop': {'v': 1, 'cdt': 1713002092000}, 'ta': {'v': 0, 'cdt': 1712735722000}, 'mcc1': {'v': 420, 'cdt': 1711974152000}, 'mnc1': {'v': 3, 'cdt': 1711974152000}}, 'prms': {'protocol': 'bce', 'spd': 7, 'sat': 12, 'hdop': 1, 'odometer': 0, 'di16': 1, 'di15': 0, 'di14': 0, 'di13': 0, 'di12': 0, 'di11': 0, 'di10': 0, 'di9': 0, 'di8': 1, 'di7': 1, 'di6': 0, 'di5': 1, 'di4': 0, 'di3': 0, 'di2': 0, 'di1': 1, 'ePwrV': 29.025, 'ai4': 1445, 'iPwrV': 4.054, 'ta': 0, 'mcc1': 420, 'mnc1': 3, 'lac1': 7771, 'cid1': 49143, 'rssi1': 96}, 'devPrms': ['protocol', 'spd', 'sat', 'hdop', 'odometer', 'di16', 'di15', 'di14', 'di13', 'di12', 'di11', 'di10', 'di9', 'di8', 'di7', 'di6', 'di5', 'di4', 'di3', 'di2', 'di1', 'ePwrV', 'ai4', 'iPwrV', 'ta', 'mcc1', 'mnc1', 'lac1', 'cid1', 'rssi1'], 'old_params': {'protocol': 'bce', 'spd': 8, 'sat': 12, 'hdop': 1, 'odometer': 0, 'di16': 1, 'di15': 0, 'di14': 0, 'di13': 0, 'di12': 0, 'di11': 0, 'di10': 0, 'di9': 0, 'di8': 1, 'di7': 1, 'di6': 0, 'di5': 1, 'di4': 0, 'di3': 0, 'di2': 0, 'di1': 1, 'ePwrV': 29.042, 'ai4': 1466, 'iPwrV': 4.054, 'ta': 0, 'mcc1': 420, 'mnc1': 3, 'lac1': 7771, 'cid1': 49143, 'rssi1': 93}, 'vLoc': 1, 'vCon': 1, 'ip': '109.83.242.42', 'rl': 0.0658, 'trl': 8603.2072, 'mdu': 30, 'tmdu': 499176, 'eidl': 0, 'teidl': 486628, 'fc': 0.007896, 'tfc': 0.0102, 'acc': 1, 'accOn': 9289960, 'accOff': 6960874, 'sdu': 0, 'tsdu': 0, 'lat': 18.24733543395996, 'lng': 42.67820358276367}, 'counters': {'engine_hours': 9289960, 'last_acc': 1, 'odometer': 8603.2072, 'engine_hours_type': 'acc', 'odometer_type': 'gps'}, 'is_wasl_connected': 'Connected', 'iconUrl': 'https://api.afaqy.sa/images/units/icons/icon.png', 'hasCCTV': False}
[2024-04-16T06:11:33.286+0000] {warnings.py:109} WARNING - /home/***/.local/lib/python3.8/site-packages/elasticsearch/_sync/client/__init__.py:399: SecurityWarning: Connecting to 'https://dbelk3.afaqy.local:9200' using TLS with verify_certs=False is insecure
  _transport = transport_class(

[2024-04-16T06:11:33.347+0000] {warnings.py:109} WARNING - /home/***/.local/lib/python3.8/site-packages/elasticsearch/_sync/client/__init__.py:399: SecurityWarning: Connecting to 'https://dbelk2.afaqy.local:9200' using TLS with verify_certs=False is insecure
  _transport = transport_class(

[2024-04-16T06:11:33.426+0000] {warnings.py:109} WARNING - /home/***/.local/lib/python3.8/site-packages/elasticsearch/_sync/client/__init__.py:399: SecurityWarning: Connecting to 'https://dbelk1.afaqy.local:9200' using TLS with verify_certs=False is insecure
  _transport = transport_class(

[2024-04-16T06:11:33.442+0000] {_transport.py:358} INFO - GET https://dbelk3.afaqy.local:9200/_cluster/health [status:N/A duration:0.004s]
[2024-04-16T06:11:33.442+0000] {_node_pool.py:249} WARNING - Node <Urllib3HttpNode(https://dbelk3.afaqy.local:9200)> has failed for 1 times in a row, putting on 1 second timeout
[2024-04-16T06:11:33.443+0000] {_transport.py:395} WARNING - Retrying request after failure (attempt 0 of 3)
Traceback (most recent call last):
  File "/home/airflow/.local/lib/python3.8/site-packages/elastic_transport/_transport.py", line 328, in perform_request
    meta, raw_data = node.perform_request(
  File "/home/airflow/.local/lib/python3.8/site-packages/elastic_transport/_node/_http_urllib3.py", line 202, in perform_request
    raise err from None
elastic_transport.ConnectionError: Connection error caused by: NewConnectionError(<urllib3.connection.HTTPSConnection object at 0x7faa1854fc40>: Failed to establish a new connection: [Errno 111] Connection refused)
[2024-04-16T06:11:33.465+0000] {warnings.py:109} WARNING - /home/***/.local/lib/python3.8/site-packages/urllib3/connectionpool.py:1061: InsecureRequestWarning: Unverified HTTPS request is being made to host 'dbelk1.afaqy.local'. Adding certificate verification is strongly advised. See: https://urllib3.readthedocs.io/en/1.26.x/advanced-usage.html#ssl-warnings
  warnings.warn(

[2024-04-16T06:11:33.528+0000] {_transport.py:335} INFO - GET https://dbelk1.afaqy.local:9200/_cluster/health [status:200 duration:0.083s]
[2024-04-16T06:11:34.260+0000] {warnings.py:109} WARNING - /home/***/.local/lib/python3.8/site-packages/urllib3/connectionpool.py:1061: InsecureRequestWarning: Unverified HTTPS request is being made to host 'dbelk2.afaqy.local'. Adding certificate verification is strongly advised. See: https://urllib3.readthedocs.io/en/1.26.x/advanced-usage.html#ssl-warnings
  warnings.warn(

[2024-04-16T06:11:34.284+0000] {_transport.py:335} INFO - PUT https://dbelk2.afaqy.local:9200/units_statistics_***/_bulk [status:429 duration:0.060s]
[2024-04-16T06:11:34.285+0000] {_node_pool.py:249} WARNING - Node <Urllib3HttpNode(https://dbelk2.afaqy.local:9200)> has failed for 1 times in a row, putting on 1 second timeout
[2024-04-16T06:11:34.285+0000] {_transport.py:427} WARNING - Retrying request after non-successful status 429 (attempt 0 of 3)
[2024-04-16T06:11:34.285+0000] {warnings.py:109} WARNING - /home/***/.local/lib/python3.8/site-packages/urllib3/connectionpool.py:1061: InsecureRequestWarning: Unverified HTTPS request is being made to host 'dbelk1.afaqy.local'. Adding certificate verification is strongly advised. See: https://urllib3.readthedocs.io/en/1.26.x/advanced-usage.html#ssl-warnings
  warnings.warn(

[2024-04-16T06:11:34.564+0000] {_transport.py:335} INFO - PUT https://dbelk1.afaqy.local:9200/units_statistics_***/_bulk [status:200 duration:0.279s]
[2024-04-16T06:11:34.700+0000] {taskinstance.py:2731} ERROR - Task failed with exception
Traceback (most recent call last):
  File "/home/airflow/.local/lib/python3.8/site-packages/airflow/models/taskinstance.py", line 444, in _execute_task
    result = _execute_callable(context=context, **execute_callable_kwargs)
  File "/home/airflow/.local/lib/python3.8/site-packages/airflow/models/taskinstance.py", line 414, in _execute_callable
    return execute_callable(context=context, **execute_callable_kwargs)
  File "/home/airflow/.local/lib/python3.8/site-packages/airflow/decorators/base.py", line 241, in execute
    return_value = super().execute(context)
  File "/home/airflow/.local/lib/python3.8/site-packages/airflow/operators/python.py", line 200, in execute
    return_value = self.execute_callable()
  File "/home/airflow/.local/lib/python3.8/site-packages/airflow/operators/python.py", line 217, in execute_callable
    return self.python_callable(*self.op_args, **self.op_kwargs)
  File "/opt/airflow/dags/Units_dag.py", line 103, in ETL_job
    Elk_client.elk_pushData(Globals.index_name,units_list_update)
  File "/opt/airflow/dags/elk_manager.py", line 69, in elk_pushData
    helpers.bulk(self.elk_client, docs_list, index=index_name, chunk_size=batch)
  File "/home/airflow/.local/lib/python3.8/site-packages/elasticsearch/helpers/actions.py", line 521, in bulk
    for ok, item in streaming_bulk(
  File "/home/airflow/.local/lib/python3.8/site-packages/elasticsearch/helpers/actions.py", line 436, in streaming_bulk
    for data, (ok, info) in zip(
  File "/home/airflow/.local/lib/python3.8/site-packages/elasticsearch/helpers/actions.py", line 355, in _process_bulk_chunk
    yield from gen
  File "/home/airflow/.local/lib/python3.8/site-packages/elasticsearch/helpers/actions.py", line 274, in _process_bulk_chunk_success
    raise BulkIndexError(f"{len(errors)} document(s) failed to index.", errors)
elasticsearch.helpers.BulkIndexError: 10000 document(s) failed to index.
[2024-04-16T06:11:34.983+0000] {taskinstance.py:1149} INFO - Marking task as UP_FOR_RETRY. dag_id=Units_statistics_DAG, task_id=ETL_job, map_index=15, execution_date=20240416T050000, start_date=20240416T061111, end_date=20240416T061134
[2024-04-16T06:11:34.999+0000] {standard_task_runner.py:107} ERROR - Failed to execute job 3753 for task ETL_job (10000 document(s) failed to index.; 325827)
[2024-04-16T06:11:35.047+0000] {local_task_job_runner.py:234} INFO - Task exited with return code 1
[2024-04-16T06:11:35.073+0000] {taskinstance.py:3312} INFO - 0 downstream tasks scheduled from follow-on schedule check
